Workbook

Sheet Harian
C1: PT. LEADY GAS LINDO
C2: PERTASHOP 3P.34.117
C3: Bantarsari, Bungursari Kota Tasikmalaya
A6: Tanggal : | B6: 1 Maret | F6: Jam Masuk : | G6: 0.20833333
A7: Oprator 1 : | B7: Argi | F7: Jam Keluar : | G7: 0.875
A8: Oprator2 : | B8: Rafandi
A11: Mesin | B11: Prodak | C11: Totalisator awal | D11: Totalisator akhir | E11: Terjual | F11: Total | G11: Harga | H11: Jumlah
A12: 1 | B12: Pertamax 1 | C12: 30685 | D12: 31100 | E12: =D12-C12 -> 415 | F12: =E12+E13 -> 900 | G12: 12200 | H12: =F12*G12 -> 10980000
B13: Pertamax 2 | C13: 31872 | D13: 32357 | E13: =D13-C13 -> 485
B14: Dex 1 | C14: 6601 | D14: 6601 | E14: =D14-C14 -> 0 | F14: =E14+E15 -> 10 | G14: 14500 | H14: =G14*F14 -> 145000
B15: Dex 2 | C15: 6609 | D15: 6619 | E15: =D15-C15 -> 10
G16: Penjualan | H16: =H12+H14 -> 11125000
A17: Lembar | B17: =H26 -> 10708000 | G17: Titipan | H17: 10000000
A18: Koin | B18: 10000 | G18: Pengeluaran | H18: 407000
A19: Jumlah | B19: =SUM(B17:B18) -> 10718000 | G19: SISA | H19: =H16-H17-H18 -> 718000
A22: Penjualan
A23: Pertamax | B23: =F12 -> 900 | F23: Pendapatan | H23: =H16 -> 11125000
A24: dex | B24: =F14 -> 10 | F24: Pengeluaran | H24: =H18 -> 407000
F25: Koin | H25: =B18 -> 10000
F26: SISA | H26: =H23-H24-H25 -> 10708000
C46: PT. LEADY GAS LINDO
C47: PERTASHOP 3P.34.117
C48: Bantarsari, Bungursari Kota Tasikmalaya
A51: Tanggal : | B51: 2 Maret | F51: Jam Masuk : | G51: 0.20833333
A52: Oprator 1 : | B52: Rafandi | F52: Jam Keluar : | G52: 0.875
A53: Oprator2 : | B53: Anisa
A56: Mesin | B56: Prodak | C56: Totalisator awal | D56: Totalisator akhir | E56: Terjual | F56: Total | G56: Harga | H56: Jumlah
A57: 1 | B57: Pertamax 1 | C57: =D12 -> 31100 | D57: 31607 | E57: =D57-C57 -> 507 | F57: =SUM(E57:E58) -> 1090 | G57: 12200 | H57: =F57*G57 -> 13298000
B58: Pertamax 2 | C58: =D13 -> 32357 | D58: 32940 | E58: =D58-C58 -> 583
B59: Dex 1 | C59: =D14 -> 6601 | D59: 6601 | E59: =D59-C59 -> 0 | F59: =E59:E60 -> 0 | G59: 14500 | H59: =G59*F59 -> 0
B60: Dex 2 | C60: =D15 -> 6619 | D60: 6619 | E60: =D60-C60 -> 0
G61: Penjualan | H61: =H57+H59 -> 13298000
A62: Lembar | B62: =H71 -> 12720000 | G62: Titipan | H62: 12000000
A63: Koin | B63: 5000 | G63: Pengeluaran | H63: 573000
A64: Jumlah | B64: =SUM(B62:B63) -> 12725000 | G64: SISA | H64: =H61-H62-H63 -> 725000
A67: Penjualan
A68: Pertamax | B68: =F57 -> 1090 | F68: Pendapatan | H68: =H61 -> 13298000
A69: dex | B69: =F59 -> 0 | F69: Pengeluaran | H69: =H63 -> 573000
F70: Koin | H70: =B63 -> 5000
F71: SISA | H71: =H68-H69-H70 -> 12720000
...

Sheet Stok
I1: Pertamax
A2: Tanggal | B2: Stok Awal | C2: Kiriman | D2: Jumlah | E2: Penjualan | F2: JML Stok Teoritis | G2: Stok Akhir | H2: Selisih | I2: Jadwal | J2: Nama Supir
A3: 46082 | B3: 6646 | C3: 0 | D3: =B3+C3 -> 6646 | E3: =Harian!F12 -> 900 | F3: =D3-E3 -> 5746 | G3: 5744 | H3: =G3-F3 -> -2
A4: 46083 | B4: =G3 -> 5744 | C4: 0 | D4: =B4+C4 -> 5744 | E4: 1090 | F4: =D4-E4 -> 4654 | G4: 4649 | H4: =G4-F4 -> -5
A5: 46084 | B5: =G4 -> 4649 | D5: =B5+C5 -> 4649 | E5: 939 | F5: =D5-E5 -> 3710 | G5: 3702 | H5: =G5-F5 -> -8
A6: 46085 | B6: =G5 -> 3702 | C6: 5000 | D6: =B6+C6 -> 8702 | E6: 949 | F6: =D6-E6 -> 7753 | G6: 7757 | H6: =G6-F6 -> 4
A7: 46086 | B7: =G6 -> 7757 | C7: 0 | D7: =B7+C7 -> 7757 | E7: =Harian!F192 -> 1032 | F7: =D7-E7 -> 6725 | G7: 6730 | H7: =G7-F7 -> 5
A8: 46087 | B8: =G7 -> 6730 | C8: 0 | D8: =B8+C8 -> 6730 | E8: 975 | F8: =D8-E8 -> 5755 | G8: 5754 | H8: =G8-F8 -> -1
A9: 46088 | B9: =G8 -> 5754 | C9: 0 | D9: =B9+C9 -> 5754 | E9: =Harian!F282 -> 1090 | F9: =D9-E9 -> 4664 | G9: 4659 | H9: =G9-F9 -> -5
A10: 46089 | B10: =G9 -> 4659 | C10: 0 | D10: =B10+C10 -> 4659 | E10: =Harian!F327 -> 902 | F10: =D10-E10 -> 3757 | G10: 3749 | H10: =G10-F10 -> -8
A11: 46090 | B11: =G10 -> 3749 | C11: 5000 | D11: =B11+C11 -> 8749 | E11: 909 | F11: =D11-E11 -> 7840 | G11: 7848 | H11: =G11-F11 -> 8
A12: 46091 | B12: =G11 -> 7848 | C12: 0 | D12: =B12+C12 -> 7848 | E12: 862 | F12: =D12-E12 -> 6986 | G12: 6988 | H12: =G12-F12 -> 2
A13: 46092 | B13: =G12 -> 6988 | C13: 0 | D13: =B13+C13 -> 6988 | E13: 1141 | F13: =D13-E13 -> 5847 | G13: 5844 | H13: =G13-F13 -> -3
A14: 46093 | B14: =G13 -> 5844 | C14: 0 | D14: =B14+C14 -> 5844 | E14: =Harian!F507 -> 958 | F14: =D14-E14 -> 4886 | G14: 4881 | H14: =G14-F14 -> -5
A15: 46094 | B15: =G14 -> 4881 | C15: 0 | D15: =B15+C15 -> 4881 | E15: =Harian!F552 -> 1033 | F15: =D15-E15 -> 3848 | G15: 3842 | H15: =G15-F15 -> -6
A16: 46095 | B16: =G15 -> 3842 | C16: 5000 | D16: =B16+C16 -> 8842 | E16: =Harian!F597 -> 1179 | F16: =D16-E16 -> 7663 | G16: 7670 | H16: =G16-F16 -> 7
A17: 46096 | B17: =G16 -> 7670 | C17: 0 | D17: =B17+C17 -> 7670 | E17: =Harian!F642 -> 942 | F17: =D17-E17 -> 6728 | G17: 6730 | H17: =G17-F17 -> 2
A18: 46097 | B18: =G17 -> 6730 | C18: 0 | D18: =B18+C18 -> 6730 | E18: 1222 | F18: =D18-E18 -> 5508 | G18: 5507 | H18: =G18-F18 -> -1
A19: 46098 | B19: =G18 -> 5507 | C19: 0 | D19: =B19+C19 -> 5507 | E19: 1132 | F19: =D19-E19 -> 4375 | G19: 4368 | H19: =G19-F19 -> -7
A20: 46099 | B20: =G19 -> 4368 | C20: 5000 | D20: =B20+C20 -> 9368 | E20: 1575 | F20: =D20-E20 -> 7793 | G20: 7795 | H20: =G20-F20 -> 2
A21: 46100 | B21: =G20 -> 7795 | C21: 0 | D21: =B21+C21 -> 7795 | E21: =Harian!F822 -> 1438 | F21: =D21-E21 -> 6357 | G21: 6362 | H21: =G21-F21 -> 5
A22: 46101 | B22: =G21 -> 6362 | C22: 0 | D22: =B22+C22 -> 6362 | E22: =Harian!F867 -> 1900 | F22: =D22-E22 -> 4462 | G22: 4453 | H22: =G22-F22 -> -9
A23: 46102 | B23: =G22 -> 4453 | C23: 0 | D23: =B23+C23 -> 4453 | E23: 1088 | F23: =D23-E23 -> 3365 | G23: 3358 | H23: =G23-F23 -> -7
A24: 46103 | B24: =G23 -> 3358 | C24: 5000 | D24: =B24+C24 -> 8358 | E24: 1141 | F24: =D24-E24 -> 7217 | G24: 7209 | H24: =G24-F24 -> -8
A25: 46104 | B25: =G24 -> 7209 | C25: 0 | D25: =B25+C25 -> 7209 | E25: 1250 | F25: =D25-E25 -> 5959 | G25: 5951 | H25: =G25-F25 -> -8
A26: 46105 | B26: =G25 -> 5951 | C26: 0 | D26: =B26+C26 -> 5951 | E26: 1292 | F26: =D26-E26 -> 4659 | G26: 4652 | H26: =G26-F26 -> -7
A27: 46106 | B27: =G26 -> 4652 | C27: 0 | D27: =B27+C27 -> 4652 | E27: 2332 | F27: =D27-E27 -> 2320 | G27: 2315 | H27: =G27-F27 -> -5
A28: 46107 | B28: =G27 -> 2315 | C28: 5000 | D28: =B28+C28 -> 7315 | E28: =Harian!F1137 -> 1155 | F28: =D28-E28 -> 6160 | G28: 6164 | H28: =G28-F28 -> 4
A29: 46108 | B29: =G28 -> 6164 | C29: 0 | D29: =B29+C29 -> 6164 | E29: 894 | F29: =D29-E29 -> 5270 | G29: 5266 | H29: =G29-F29 -> -4
A30: 46109 | B30: =G29 -> 5266 | D30: =B30+C30 -> 5266 | F30: =D30-E30 -> 5266 | H30: =G30-F30 -> -5266
A31: 46110 | B31: =G30 -> 0 | D31: =B31+C31 -> 0 | F31: =D31-E31 -> 0 | H31: =G31-F31 -> 0
A32: 46111 | B32: =G31 -> 0 | D32: =B32+C32 -> 0 | F32: =D32-E32 -> 0 | H32: =G32-F32 -> 0
A33: 46112 | B33: =G32 -> 0 | D33: =B33+C33 -> 0 | F33: =D33-E33 -> 0 | H33: =G33-F33 -> 0
C34: =SUM(C3:C33) -> 30000 | E34: =SUM(E3:E33) -> 31320
I35: Dex
A36: Tanggal | B36: Stok Awal | C36: Kiriman | D36: Jumlah | E36: Penjualan | F36: JML Stok Teoritis | G36: Stok Akhir | H36: Selisih | I36: Jadwal | J36: Nama Supir
A37: 45717 | B37: 6158 | C37: 0 | D37: =B37+C37 -> 6158 | E37: =Harian!F14 -> 10 | F37: =D37-E37 -> 6148 | G37: 6148 | H37: =G37-F37 -> 0
A38: 45718 | B38: =G37 -> 6148 | C38: 0 | D38: =B38+C38 -> 6148 | E38: 0 | F38: =D38-E38 -> 6148 | G38: 6148 | H38: =G38-F38 -> 0
A39: 45719 | B39: =G38 -> 6148 | C39: 0 | D39: =B39+C39 -> 6148 | E39: 63 | F39: =D39-E39 -> 6085 | G39: 6085 | H39: =G39-F39 -> 0
A40: 45720 | B40: =G39 -> 6085 | C40: 0 | D40: =B40+C40 -> 6085 | E40: 25 | F40: =D40-E40 -> 6060 | G40: 6060 | H40: =G40-F40 -> 0
...

Sheet Kas
C1: Kas Lemari | H1: Arus Kas
A2: Tanggal | B2: Ket | C2: Debit | D2: Kredit | E2: jumlah | F2: Tanggal | G2: Ket | H2: Debit | I2: Kredit | J2: jumlah
A3: 46082 | B3: Sisa kas | C3: 3905000 | E3: =C3-D3 -> 3905000 | F3: 46082 | G3: Sisa kas | H3: 14305000 | J3: =H3-I3 -> 14305000
B4: Penjualan | C4: 11125000 | E4: =E3+C4-D4 -> 15030000 | G4: Penjualan | H4: =C4 -> 11125000 | J4: =J3+H4-I4 -> 25430000
B5: Qris | D5: 107000 | E5: =E4+C5-D5 -> 14923000 | G5: Qris | I5: =D5 -> 107000 | J5: =J4+H5-I5 -> 25323000
B6: Debit | D6: 300000 | E6: =E5+C6-D6 -> 14623000 | G6: Debit | I6: =D6 -> 300000 | J6: =J5+H6-I6 -> 25023000
B7: Setoran | D7: 10000000 | E7: =E6+C7-D7 -> 4623000 | F7: 46083 | G7: Penjualan | H7: 13298000 | J7: =J6+H7-I7 -> 38321000
A8: 46083 | B8: Penjualan | C8: 13298000 | E8: =E7+C8-D8 -> 17921000 | G8: Qris | I8: 343000 | J8: =J7+H8-I8 -> 37978000
B9: Qris | D9: 343000 | E9: =E8+C9-D9 -> 17578000 | G9: Debit | I9: 200000 | J9: =J8+H9-I9 -> 37778000
B10: Debit | D10: 200000 | E10: =E9+C10-D10 -> 17378000 | G10: Proposal | I10: 30000 | J10: =J9+H10-I10 -> 37748000
B11: Proposal | D11: 30000 | E11: =E10+C11-D11 -> 17348000 | F11: 46056 | G11: Penjualan | H11: 12369300 | J11: =J10+H11-I11 -> 50117300
B12: Setoran | D12: 14000000 | E12: =E11+C12-D12 -> 3348000 | G12: Qris | I12: 101000 | J12: =J11+H12-I12 -> 50016300
A13: 46084 | B13: Penjualan | C13: 12369300 | E13: =E12+C13-D13 -> 15717300 | G13: Debit | I13: 50000 | J13: =J12+H13-I13 -> 49966300
B14: Qris | D14: 101000 | E14: =E13+C14-D14 -> 15616300 | G14: Sampah | I14: 10000 | J14: =J13+H14-I14 -> 49956300
B15: Debit | D15: 50000 | E15: =E14+C15-D15 -> 15566300 | F15: 46085 | G15: AMT | I15: 50000 | J15: =J14+H15-I15 -> 49906300
B16: Sampah | D16: 10000 | E16: =E15+C16-D16 -> 15556300 | G16: Penjualan | H16: 11940300 | J16: =J15+H16-I16 -> 61846600
B17: Setoran | D17: 12000000 | E17: =E16+C17-D17 -> 3556300 | G17: Qris | I17: 213000 | J17: =J16+H17-I17 -> 61633600
A18: 46085 | B18: AMT | D18: 50000 | E18: =E17+C18-D18 -> 3506300 | F18: 46086 | G18: Penjualan | H18: =C22 -> 13532900 | J18: =J17+H18-I18 -> 75166500
B19: Penjualan | C19: 11940300 | E19: =E18+C19-D19 -> 15446600 | G19: Qris | I19: 105000 | J19: =J18+H19-I19 -> 75061500
B20: Qris | D20: 213000 | E20: =E19+C20-D20 -> 15233600 | F20: 46087 | G20: Penjualan | H20: =C25 -> 12185000 | J20: =J19+H20-I20 -> 87246500
B21: Setoran | D21: 12000000 | E21: =E20+C21-D21 -> 3233600 | G21: Qris | I21: 179000 | J21: =J20+H21-I21 -> 87067500
A22: 46086 | B22: Penjualan | C22: 13532900 | E22: =E21+C22-D22 -> 16766500 | F22: 46088 | G22: Stor Bank | I22: 50000000 | J22: =J21+H22-I22 -> 37067500
B23: Qris | D23: 105000 | E23: =E22+C23-D23 -> 16661500 | G23: Penjualan | H23: =C28 -> 13312500 | J23: =J22+H23-I23 -> 50380000
B24: Setoran | D24: 13000000 | E24: =E23+C24-D24 -> 3661500 | G24: Qris | I24: 182294 | J24: =J23+H24-I24 -> 50197706
A25: 46087 | B25: Penjualan | C25: =Harian!H248 -> 12185000 | E25: =E24+C25-D25 -> 15846500 | F25: 46089 | G25: Penjualan | H25: =C31 -> 12265900 | J25: =J24+H25-I25 -> 62463606
B26: Qris | D26: 179000 | E26: =E25+C26-D26 -> 15667500 | G26: Qris | I26: =D32 -> 161400 | J26: =J25+H26-I26 -> 62302206
B27: Setoran | D27: 11000000 | E27: =E26+C27-D27 -> 4667500 | G27: Cam Switch | I27: 550000 | J27: =J26+H27-I27 -> 61752206
A28: 46088 | B28: Penjualan | C28: =Harian!H293 -> 13312500 | E28: =E27+C28-D28 -> 17980000 | F28: 46090 | G28: Penjualan | H28: 12162800 | J28: =J27+H28-I28 -> 73915006
B29: Qris | D29: 182294 | E29: =E28+C29-D29 -> 17797706 | G29: Curah | I29: 50000 | J29: =J28+H29-I29 -> 73865006
B30: Setoran | D30: 14000000 | E30: =E29+C30-D30 -> 3797706 | G30: Qris | I30: 575000 | J30: =J29+H30-I30 -> 73290006
A31: 46089 | B31: Penjualan | C31: 12265900 | E31: =E30+C31-D31 -> 16063606 | F31: 46091 | G31: Penjualan | H31: 10951400 | J31: =J30+H31-I31 -> 84241406
B32: Qris | D32: 161400 | E32: =E31+C32-D32 -> 15902206 | G32: Sampah | I32: 50000 | J32: =J31+H32-I32 -> 84191406
B33: Setoran | D33: 10000000 | E33: =E32+C33-D33 -> 5902206 | G33: TF | I33: 100000 | J33: =J32+H33-I33 -> 84091406
A34: 46090 | B34: Penjualan | C34: 12162800 | E34: =E33+C34-D34 -> 18065006 | G34: Qris | I34: 216000 | J34: =J33+H34-I34 -> 83875406
B35: Curah | D35: 50000 | E35: =E34+C35-D35 -> 18015006 | F35: 46092 | G35: Penjualan | H35: 14123200 | J35: =J34+H35-I35 -> 97998606
B36: Qris | D36: 575000 | E36: =E35+C36-D36 -> 17440006 | G36: Qris | I36: 475000 | J36: =J35+H36-I36 -> 97523606
B37: Setoran | D37: 13000000 | E37: =E36+C37-D37 -> 4440006 | F37: 46093 | G37: Penjualan | H37: =C46 -> 12470600 | J37: =J36+H37-I37 -> 109994206
A38: 46091 | B38: Penjualan | C38: 10951400 | E38: =E37+C38-D38 -> 15391406 | G38: Qris | I38: =D47 -> 300000 | J38: =J37+H38-I38 -> 109694206
B39: Sampah | D39: 50000 | E39: =E38+C39-D39 -> 15341406 | G39: Debit | I39: =D48 -> 250000 | J39: =J38+H39-I39 -> 109444206
B40: TF | D40: 100000 | E40: =E39+C40-D40 -> 15241406 | G40: Stor Bank | I40: 82850000 | J40: =J39+H40-I40 -> 26594206
...

Sheet Pengeluaran
A1: Pengeluaran oprasional Pertashop PT Leady Gas Lindo 3P.46.117 Maret 2026
A7: Oprasional | E7: Curah
A8: 46083 | B8: Proposal | C8: 30000 | E8: 46085 | F8: 50000
A9: 46084 | B9: Sampah | C9: 10000 | E9: 46090 | F9: 50000
A10: 46089 | B10: Cam switch | C10: 550000 | E10: 46095 | F10: 50000
A11: 46091 | B11: Sampah | C11: 10000 | E11: 46099 | F11: 50000
A12: 46093 | B12: Indihome | C12: 286050 | E12: 46103 | F12: 50000
B13: Listrik | C13: 1182495 | E13: 46107 | F13: 50000
A14: 46096 | B14: Sampah | C14: 20000
A15: 46097 | B15: Galon | C15: 22500
A16: 46098 | B16: Sampah | C16: 10000
A17: 46099 | B17: pompa | C17: 480000
A18: 46106 | B18: Sampah | C18: 10000

Sheet losis
A1: REKAPITULASI LOSIS Pertashop PT Leady Gas Lindo 3P.46.117 Maret 2025
A7: PERTAMAX
A8: Stok Awal Per Maret 2026 | B8: = | C8: =Stok!B3 -> 6646
A9: Do Penebusan Per Maret 2026 | B9: = | C9: =Stok!C34 -> 30000
A10: Jumlah Stok Per Maret 2026 Do penebusan | D10: = | E10: =SUM(C8:C9) -> 36646
A12: Total Penjualan Per Maret 2026 | B12: = | C12: =Stok!E34 -> 31320
A13: Stok Akhir Per Maret 2026 | B13: = | C13: =Stok!G33 -> 0
A14: Jumlah penjualan Per Maret 2026+ stok akhir Per Maret 2026 | D14: = | E14: =SUM(C12:C13) -> 31320
A16: Losis | D16: = | E16: =E10-E14 -> 5326
A17: Persentase | D17: = | E17: =(E16/C12)*100 -> 17.005109
A18: DEX
A19: Stok Awal Per Maret 2026 | B19: = | C19: =Stok!B37 -> 6158
A20: Do Penebusan Per Maret 2026 | B20: = | C20: =Stok!C68 -> 0
A21: Jumlah Stok Per Maret 2026 Do penebusan | D21: = | E21: =SUM(C19:C20) -> 6158
A23: Total Penjualan Per Maret 2026 | B23: = | C23: =Stok!E68 -> 1044
A24: Stok Akhir Per Maret 2026 | B24: = | C24: =Stok!G61 -> 5234
A25: Jumlah penjualan Per Maret 2026+ stok akhir Per Maret 2026 | D25: = | E25: =SUM(C23:C24) -> 6278
A27: Losis | D27: = | E27: =E21-E25 -> -120
A28: Persentase | D28: = | E28: =(C24/E27)*100 -> -4361.6667

Sheet TOT Akhir
A1: Totalisator Akhir Bulan Pertashop PT Leady Gas Lindo 3P.46.117 Maret 2025
A7: Produk | B7: Nozzel | C7: Totalisator akhir | D7: Totalisator awal | E7: Terjual | F7: Tera bbm | G7: liter | H7: Harga | I7: Jumlah
A8: Pertamax | B8: 1 | D8: =Harian!C12 -> 30685 | E8: =C8-D8 -> -30685 | F8: 0 | G8: =E8+E9-F8 -> -62557 | H8: 12200 | I8: =G8*H8 -> -763195400
B9: 2 | D9: =Harian!C13 -> 31872 | E9: =C9-D9 -> -31872
A10: Dex | B10: 1 | D10: =Harian!C14 -> 6601 | E10: =C10-D10 -> -6601 | F10: 0 | G10: =E10+E11-F10 -> -13210 | H10: 14500 | I10: =G10*H10 -> -191545000
B11: 2 | D11: =Harian!C15 -> 6609 | E11: =C11-D11 -> -6609
G12: Jumlah Pendapatan | I12: =SUM(I8:I11) -> -954740400
E13: Total Pendapatan Laba
E14: Pertamax | F14: =G8 -> -62557 | G14: x | H14: 600 | I14: =F14*H14 -> -37534200
E15: Dex | F15: =G10 -> -13210 | G15: x | H15: 600 | I15: =F15*H15 -> -7926000
H16: Jumlah | I16: =SUM(I14:I15) -> -45460200
A17: Pengeluaran
A18: 1 | B18: Gaji Karyawan
A19: 2 | B19: Kas
A20: 3 | B20: PPH
A21: 4 | B21: Admin EDC
B23: Jumlah | C23: =SUM(C18:C22) -> 0
A25: Lossis
A26: 1 | B26: =E14 -> Pertamax | C26: =losis!E16 -> 5326 | D26: X | E26: 11600 | G26: =C26*E26 -> 61781600 | H26: =losis!E17 -> 17.005109
A27: 2 | B27: =E15 -> Dex | C27: =losis!E27 -> -120 | D27: X | E27: 13900 | G27: =E27*C27 -> -1668000 | H27: =losis!E28 -> -4361.6667
H28: =SUM(G26:G27) -> 60113600
G29: Jumlah Total Pengeluaran | I29: =SUM(C23,H28) -> 60113600
G30: Laba Bersih | I30: =I16-I29 -> -105573800

Sheet EDC
B1: PT. LEADY GAS LINDO
B2: PERTASHOP 3P.46.117
B3: Bantarsari, Bungursari Kota Tasikmalaya
A6: QRIS | B6: 0.003
A7: Debit | B7: 0.005
A8: Tanggal | B8: Keterangan | C8: Potongan | D8: Harga | E8: Jumlah Masuk | F8: Jumlah Potongan
A9: 46082 | B9: QRIS | C9: 0.3 | D9: 107000 | E9: =D9-D9*C9% -> 106679 | F9: =D9-E9 -> 321
B10: Debit | C10: 0.5 | D10: 300000 | E10: =D10-D10*C10% -> 298500 | F10: =D10-E10 -> 1500
A11: 46083 | B11: QRIS | C11: 0.3 | D11: 343000 | E11: =D11-D11*C11% -> 341971 | F11: =D11-E11 -> 1029
B12: Debit | C12: 0.5 | D12: 200000 | E12: =D12-D12*C12% -> 199000 | F12: =D12-E12 -> 1000
A13: 46084 | B13: QRIS | C13: 0.3 | D13: 101000 | E13: =D13-D13*C13% -> 100697 | F13: =D13-E13 -> 303
B14: Debit | C14: 0.5 | D14: 50000 | E14: =D14-D14*C14% -> 49750 | F14: =D14-E14 -> 250
A15: 46085 | B15: QRIS | C15: 0.3 | D15: 213000 | E15: =D15-D15*C15% -> 212361 | F15: =D15-E15 -> 639
A16: 46086 | B16: QRIS | C16: 0.3 | D16: 105000 | E16: =D16-D16*C16% -> 104685 | F16: =D16-E16 -> 315
A17: 46087 | B17: QRIS | C17: 0.3 | D17: 159000 | E17: =D17-D17*C17% -> 158523 | F17: =D17-E17 -> 477
B18: Debit | C18: 0.5 | D18: 20000 | E18: =D18-D18*C18% -> 19900 | F18: =D18-E18 -> 100
A19: 46088 | B19: QRIS | C19: 0.3 | D19: 182294 | E19: 181747 | F19: =D19-E19 -> 547
A20: 46089 | B20: QRIS | C20: 0.3 | D20: 161400 | E20: 160916 | F20: =D20-E20 -> 484
A21: 46090 | B21: QRIS | C21: 0.3 | D21: 575000 | E21: =D21-D21*C21% -> 573275 | F21: =D21-E21 -> 1725
A22: 46091 | B22: QRIS | C22: 0.3 | D22: 216000 | E22: =D22-D22*C22% -> 215352 | F22: =D22-E22 -> 648
A23: 46092 | B23: QRIS | C23: 0.3 | D23: 475000 | E23: =D23-D23*C23% -> 473575 | F23: =D23-E23 -> 1425
A24: 46093 | B24: Debit | C24: 0.5 | D24: 250000 | E24: =D24-D24*C24% -> 248750 | F24: =D24-E24 -> 1250
B25: QRIS | C25: 0.3 | D25: 300000 | E25: =D25-D25*C25% -> 299100 | F25: =D25-E25 -> 900
A26: 46094 | B26: QRIS | C26: 0.3 | D26: 72000 | E26: =D26-D26*C26% -> 71784 | F26: =D26-E26 -> 216
A27: 46095 | B27: QRIS | C27: 0.3 | D27: 662000 | E27: =D27-D27*C27% -> 660014 | F27: =D27-E27 -> 1986
A28: 46096 | B28: QRIS | C28: 0.3 | D28: 88200 | E28: =D28-D28*C28% -> 87935.4 | F28: =D28-E28 -> 264.6
B29: Debit | C29: 0.5 | D29: 300000 | E29: =D29-D29*C29% -> 298500 | F29: =D29-E29 -> 1500
A30: 46097 | B30: QRIS | C30: 0.3 | D30: 472026 | E30: =D30-D30*C30% -> 470609.92 | F30: =D30-E30 -> 1416.078
B31: Debit | C31: 0.5 | D31: 30000 | E31: =D31-D31*C31% -> 29850 | F31: =D31-E31 -> 150
A32: 46098 | B32: QRIS | C32: 0.3 | D32: 185000 | E32: =D32-D32*C32% -> 184445 | F32: =D32-E32 -> 555
B33: Debit | C33: 0.5 | D33: 200000 | E33: =D33-D33*C33% -> 199000 | F33: =D33-E33 -> 1000
A34: 46099 | B34: QRIS | C34: 0.3 | D34: 400000 | E34: =D34-D34*C34% -> 398800 | F34: =D34-E34 -> 1200
A35: 46100 | B35: QRIS | C35: 0.3 | D35: 283800 | E35: =D35-D35*C35% -> 282948.6 | F35: =D35-E35 -> 851.4
A36: 46101 | B36: QRIS | C36: 0.3 | D36: 469000 | E36: =D36-D36*C36% -> 467593 | F36: =D36-E36 -> 1407
B37: Debit | C37: 0.5 | D37: 300000 | E37: =D37-D37*C37% -> 298500 | F37: =D37-E37 -> 1500
A38: 46102 | B38: QRIS | C38: 0.3 | D38: 721924 | E38: =D38-D38*C38% -> 719758.23 | F38: =D38-E38 -> 2165.772
B39: Debit | C39: 0.5 | D39: 338500 | E39: =D39-D39*C39% -> 336807.5 | F39: =D39-E39 -> 1692.5
A40: 46103 | B40: QRIS | C40: 0.3 | D40: 298500 | E40: =D40-D40*C40% -> 297604.5 | F40: =D40-E40 -> 895.5
B41: Debit | C41: 0.5 | D41: 351500 | E41: =D41-D41*C41% -> 349742.5 | F41: =D41-E41 -> 1757.5
A42: 46104 | B42: QRIS | C42: 0.3 | D42: 658000 | E42: =D42-D42*C42% -> 656026 | F42: =D42-E42 -> 1974
...

Sheet Kesimpulan
A1: Laporan Penerimaan dan penjualan BBM
A2: Pertashop PT LEADY GAS LINDO
A3: 3P.46.117
A4: Maret 2026
A5: Produk | B5: Stok Awal | C5: Penerimaan BBM | D5: Dispenser | E5: Totalisator Awal | F5: Totalisator Akhir | G5: Total Penjualan | H5: Stok Akhir
A6: Pertamax | B6: =[1]Stok!B3 -> 7416 | C6: =Stok!C34 -> 30000 | D6: Nozzel 1 | E6: 30685 | G6: =F6-E6 -> -30685 | H6: =Stok!G33 -> 0
D7: Nozzel 2 | E7: 31872 | G7: =F7-E7 -> -31872
A8: JUMLAH | G8: =SUM(G6:G7) -> -62557
A11: Dex | B11: =[1]Stok!B36 -> 8106 | C11: =Stok!C68 -> 0 | D11: Nozzel 1 | E11: 6601 | G11: =F11-E11 -> -6601 | H11: =Stok!G67 -> 0
D12: Nozzel 2 | E12: 6609 | G12: =F12-E12 -> -6609
A13: JUMLAH | G13: =SUM(G11:G12) -> -13210

Sheet Neraca
A1: NERACA PERDAGANGAN Pertashop PT Leady Gas Lindo 3P.46.117 Maret 2026
A7: AKTIVA
A8: Arus Kas
A9: Kas SPBU | B9: : | C9: .................................................................... | D9: : | E9: 0 | F9: = | G9: =E9+E10 -> 0
A10: Koin | B10: : | C10: .................................................................... | D10: : | E10: 0 | F10: =
A11: Tabanas Bank | B11: : | C11: .................................................................... | D11: : | E11: 0 | F11: = | G11: =E11 -> 0
A12: Inventaris | B12: : | C12: .................................................................... | D12: : | E12: 0 | F12: =
J13: =SUM(G9:I11) -> 0
A14: STOK BARANG DAGANGAN
A15: Pertamax | B15: : | C15: ( ) Cm dilihat pada tabulasi | D15: : | E15: 0 | F15: x | G15: 11600 | I15: =E15*G15 -> 0
A16: Dex | B16: : | C16: ( ) Cm dilihat pada tabulasi | D16: : | E16: 0 | F16: x | G16: 13900 | I16: =E16*G16 -> 0
J17: =SUM(I15:I18) -> 0
A20: DO BBM
A21: Pertamax | B21: : | C21: ................................................. | E21: 0 | F21: x | G21: 12200 | I21: =E21*G21 -> 0
A22: Dex | B22: : | C22: ................................................. | E22: 0 | F22: x | G22: 14500 | I22: =E22*G22 -> 0
J23: =SUM(I21:I24) -> 0
A25: FASIVA
A26: Utang jangka Pendek | B26: : | C26: .................................................................... | D26: : | E26: 0
A27: Utang Jangka Panjang | B27: : | C27: .................................................................... | D27: : | E27: 0
A28: Modal Oli | J28: 7115200
A29: Modal Gas | J29: 1520000
E30: Jumlah Harta Lancar | H30: : | J30: =J13+J17+J23+J28+J29 -> 8635200
A31: catatan neraca modal
A32: 1 | B32: : | C32: 255000000
A33: 2 | B33: :
C34: =SUM(C32:C33) -> 255000000
A37: Perputaran nerca modal
A38: =E30 -> Jumlah Harta Lancar | B38: = | C38: =C34 -> 255000000
A39: Gas | B39: = | C39: 1680000
A40: Oli | B40: = | C40: =J28 -> 7115200
A41: Perputaran Modal | C41: =C38-C39-C40 -> 246204800

Sheet Gaji
A1: Gaji Karyawan Pertashop PT Leady Gas Lindo 3P.46.117 Maret 2025
A7: Nama | B7: Besaran Gaji | C7: Lembur | D7: Kas Bon | E7: Sisa | F7: Tanda Tangan
A8: Barry | B8: 2000000 | E8: =B8+C8-D8 -> 2000000
A9: Zeny | B9: 1500000 | E9: =B9+C9-D9 -> 1500000
A10: Anisa | B10: 1350000 | E10: =B10+C10-D10 -> 1350000
A11: Argi | B11: 1200000 | E11: =B11+C11-D11 -> 1200000
A12: Rafandi | B12: 1200000 | E12: =B12+C12-D12 -> 1200000
A13: Total | B13: =SUM(B8:B12) -> 7250000 | E13: =B13+C13-D13 -> 7250000

Sheet Voucher
B3: Voucher | G3: anisa | H3: 24400
B4: PX | C4: 100000 | D4: Yuda | G4: Rafandi | H4: 24400
B5: PX | C5: 24400 | D5: Aep | G5: Argi | H5: 24400
B6: PX | C6: 24400 | D6: Dian | G6: zeny | H6: 24400
B7: PX | C7: 23058 | G7: taufik | H7: 22570
C8: 24400 | G8: Pak nanag | H8: 24400
C9: 24400 | G9: sandi | H9: 24400
C10: 50000 | D10: mg dedi | H10: =SUM(H3:H9) -> 168970
C11: 50000 | D11: mg ihsak
C12: 24400 | D12: yuyun pln
C13: 24400 | D13: teh vera material
C14: 24400 | D14: teh ucu
C15: 24400 | D15: cibunigeulis
C16: 24400 | D16: neng cici
C17: 24400 | D17: mg toyo
C18: 50000 | D18: tesa teh yuni
C19: 24400 | D19: yaya
C20: 24400 | D20: dee sely
C21: 24400 | D21: mang eeng
C22: 24400 | D22: rikeu
... C54: 24400 | D54: jajat
C55: =SUM(C4:C54) -> 1824658
